Workbook

Sheet Cover
C14: Financial & Operating Performance Analysis
C17: Table of Contents
C19: Dashboard | F19: Segment Analysis | H19: Operating Data
C20: Statement of Income | F20: Mobility Analysis | H20: Peer Comparison
C21: Statement of Financial Position | F21: Capital Intensity | H21: Outlook & Valuation
C22: Statement of Cash Flows | F22: ROIC Analysis

Sheet Dashboard
D2: Mercedes-Benz Group
B4: Dashboard
B6: All figures in € millions unless stated | I6: 2021 | J6: =I6+1 -> 2022 | K6: =J6+1 -> 2023 | L6: =K6+1 -> 2024 | M6: =L6+1 -> 2025
B8: Key Figures
B9: Revenue | I9: ='Statement of Income'!I9 -> 133893 | J9: ='Statement of Income'!J9 -> 150017 | K9: ='Statement of Income'!K9 -> 152390 | L9: ='Statement of Income'!L9 -> 145594 | M9: ='Statement of Income'!M9 -> 132214
B10: EBIT | I10: ='Statement of Income'!I21 -> 16028.229 | J10: ='Statement of Income'!J21 -> 20458.227 | K10: ='Statement of Income'!K21 -> 19660.23 | L10: ='Statement of Income'!L21 -> 13599.196 | M10: ='Statement of Income'!M21 -> 5820.1689
B11: Adjusted EBIT | I11: ='Segment Analysis'!I28 -> 17158 | J11: ='Segment Analysis'!J28 -> 20655 | K11: ='Segment Analysis'!K28 -> 20004 | L11: ='Segment Analysis'!L28 -> 13713 | M11: ='Segment Analysis'!M28 -> 8235
B12: Adjusted EBIT Margin % | I12: =I11/I9 -> 0.1281471 | J12: =J11/J9 -> 0.1376844 | K12: =K11/K9 -> 0.13126846 | L12: =L11/L9 -> 0.094186574 | M12: =M11/M9 -> 0.062285386
B13: Net Profit from Continuing Operations | I13: ='Statement of Income'!I32 -> 11050.229 | J13: ='Statement of Income'!J32 -> 14809.227 | K13: ='Statement of Income'!K32 -> 14531.23 | L13: ='Statement of Income'!L32 -> 10409.196 | M13: ='Statement of Income'!M32 -> 5331.1689
B14: Units Sold | F14: Millions | I14: ='Segment Analysis'!I12+('Segment Analysis'!I19/1000) -> 2.3262 | J14: ='Segment Analysis'!J12+('Segment Analysis'!J19/1000) -> 2.4553 | K14: ='Segment Analysis'!K12+('Segment Analysis'!K19/1000) -> 2.4878 | L14: ='Segment Analysis'!L12+('Segment Analysis'!L19/1000) -> 2.38561 | M14: ='Segment Analysis'!M12+('Segment Analysis'!M19/1000) -> 2.159136
B15: Industrial Free Cash Flow | I15: ='Capital Intensity'!I33 -> 7880 | J15: ='Capital Intensity'!J33 -> 8128 | K15: ='Capital Intensity'!K33 -> 11316 | L15: ='Capital Intensity'!L33 -> 9152 | M15: ='Capital Intensity'!M33 -> 5414
B16: Adjusted Industrial Free Cash Flow (FCF) | I16: ='Capital Intensity'!I34 -> 10125 | J16: ='Capital Intensity'!J34 -> 9294 | K16: ='Capital Intensity'!K34 -> 11720 | L16: ='Capital Intensity'!L34 -> 9421 | M16: ='Capital Intensity'!M34 -> 5856
B17: Net Industrial Debt / (Net Liquidity) | I17: =-'Operating Data'!I57 -> -21005 | J17: =-'Operating Data'!J57 -> -26637 | K17: =-'Operating Data'!K57 -> -31069 | L17: =-'Operating Data'!L57 -> -31417 | M17: =-'Operating Data'!M57 -> -32162
B18: Top-End Mix | I18: ='Segment Analysis'!I13 -> 0.16 | J18: ='Segment Analysis'!J13 -> 0.16 | K18: ='Segment Analysis'!K13 -> 0.16 | L18: ='Segment Analysis'!L13 -> 0.14 | M18: ='Segment Analysis'!M13 -> 0.15
B19: Cars xEV Share (Electrified Vehicles) | I19: ='Operating Data'!I42 -> 0.117 | J19: ='Operating Data'!J42 -> 0.16 | K19: ='Operating Data'!K42 -> 0.197 | L19: ='Operating Data'!L42 -> 0.185 | M19: ='Operating Data'!M42 -> 0.205
B22: *Group, Industrial Business and automotive segment KPIs are presented together.

Sheet Statement of Income
D2: Mercedes-Benz Group
B4: Consolidated Statement of Income
B6: All figures in € millions unless stated | I6: 2021 | J6: =I6+1 -> 2022 | K6: =J6+1 -> 2023 | L6: =K6+1 -> 2024 | M6: =L6+1 -> 2025
B9: Revenue | I9: 133893 | J9: 150017 | K9: 152390 | L9: 145594 | M9: 132214
B10: Cost Of Sales | I10: -103218 | J10: -115997 | K10: -117386 | L10: -117018 | M10: -109881
B11: Gross Profit | I11: =SUM(I9:I10) -> 30675 | J11: =SUM(J9:J10) -> 34020 | K11: =SUM(K9:K10) -> 35004 | L11: =SUM(L9:L10) -> 28576 | M11: =SUM(M9:M10) -> 22333
B12: Gross Margin % | I12: =I11/I9 -> 0.22910085 | J12: =J11/J9 -> 0.2267743 | K12: =K11/K9 -> 0.22970011 | L12: =L11/L9 -> 0.19627182 | M12: =M11/M9 -> 0.16891555
B14: Selling Expenses | I14: -9194 | J14: -9482 | K14: -10270 | L14: -9993 | M14: -9718
B15: General Administrative Expenses | I15: -2808 | J15: -2584 | K15: -2771 | L15: -2529 | M15: -2477
B16: Research And Non-Capitalized Development Costs | I16: -5467 | J16: -5602 | K16: -6230 | L16: -5580 | M16: -6055
B17: Other Operating Income | I17: 2888 | J17: 3323 | K17: 2206 | L17: 2507 | M17: 1551
B18: Other Operating Expense | I18: -1735 | J18: -1289 | K18: -516 | L18: -483 | M18: -1025
B19: Gains/Losses On Equity-Method Investments, Net | I19: 1352 | J19: 1732 | K19: 2129 | L19: 1138 | M19: 1118
B20: Other Financial Income/Expense, Net | I20: 317 | J20: 340 | K20: 108 | L20: -37 | M20: 93
B21: Earnings Before Interest and Taxes (EBIT) | I21: =SUM(I11:I20) -> 16028.229 | J21: =SUM(J11:J20) -> 20458.227 | K21: =SUM(K11:K20) -> 19660.23 | L21: =SUM(L11:L20) -> 13599.196 | M21: =SUM(M11:M20) -> 5820.1689
B22: EBIT Margin % | I22: =I21/I9 -> 0.11970924 | J22: =J21/J9 -> 0.13637272 | K22: =K21/K9 -> 0.1290126 | L22: =L21/L9 -> 0.093404922 | M22: =M21/M9 -> 0.044020822
B24: Interest Income | I24: 212 | J24: 273 | K24: 678 | L24: 738 | M24: 623
B25: Interest Expense | I25: -429 | J25: -427 | K25: -254 | L25: -190 | M25: -159
B26: Profit Before Income Taxes (EBT) | I26: =I21+SUM(I24:I25) -> 15811.229 | J26: =J21+SUM(J24:J25) -> 20304.227 | K26: =K21+SUM(K24:K25) -> 20084.23 | L26: =L21+SUM(L24:L25) -> 14147.196 | M26: =M21+SUM(M24:M25) -> 6284.1689
B27: EBT Margin % | I27: =I26/I9 -> 0.11808854 | J27: =J26/J9 -> 0.13534617 | K27: =K26/K9 -> 0.13179493 | L27: =L26/L9 -> 0.097168814 | M27: =M26/M9 -> 0.047530284
B29: Income Taxes | I29: -4761 | J29: -5495 | K29: -5553 | L29: -3738 | M29: -953
B30: Profit/Loss From Discontinued Operations After Taxes | I30: 12346 | J30: 0 | K30: 0 | L30: 0 | M30: 0
B31: Net Profit (Including Discontinued Operations) | I31: =I26+I29+I30 -> 23396.229 | J31: =J26+J29+J30 -> 14809.227 | K31: =K26+K29+K30 -> 14531.23 | L31: =L26+L29+L30 -> 10409.196 | M31: =M26+M29+M30 -> 5331.1689
B32: Net Profit from Continuing Operations | I32: =I31-I30 -> 11050.229 | J32: =J31-J30 -> 14809.227 | K32: =K31-K30 -> 14531.23 | L32: =L31-L30 -> 10409.196 | M32: =M31-M30 -> 5331.1689
B33: Net Margin % | I33: =I32/I9 -> 0.082530297 | J33: =J32/J9 -> 0.098716991 | K33: =K32/K9 -> 0.095355533 | L33: =L32/L9 -> 0.071494679 | M33: =M32/M9 -> 0.040322272

Sheet Statement of Financial Position
D2: Mercedes-Benz Group
B4: Consolidated Statement of Financial Position
B6: All figures in € millions unless stated | I6: 2021 | J6: =I6+1 -> 2022 | K6: =J6+1 -> 2023 | L6: =K6+1 -> 2024 | M6: =L6+1 -> 2025
B8: Assets
C9: Intangible Assets | I9: 15005 | J9: 15869 | K9: 17593 | L9: 19436 | M9: 20547
C10: Property, Plant And Equipment Including Right-Of-Use Assets | I10: 27859 | J10: 27250 | K10: 26090 | L10: 26537 | M10: 27340
C11: Equipment On Operating Leases | I11: 44471 | J11: 41552 | K11: 41712 | L11: 45220 | M11: 39472
C12: Equity-Method Investments | I12: 13588 | J12: 13530 | K12: 13104 | L12: 12786 | M12: 10037
C13: Receivables From Financial Services | I13: 46955 | J13: 48237 | K13: 49742 | L13: 48547 | M13: 41902
C14: Marketable Debt Securities And Similar Investments | I14: 873 | J14: 823 | K14: 699 | L14: 644 | M14: 626
C15: Other Financial Assets | I15: 3181 | J15: 4478 | K15: 4340 | L15: 3020 | M15: 2953
C16: Deferred Tax Assets | I16: 3434 | J16: 3725 | K16: 4127 | L16: 4335 | M16: 6090
C17: Income Tax Assets | I17: 0 | J17: 0 | K17: 318 | L17: 327 | M17: 426
C18: Other Assets | I18: 1536 | J18: 1677 | K18: 1265 | L18: 2391 | M18: 3941
B19: Total Non-Current Assets | I19: =SUM(I9:I18) -> 156902 | J19: =SUM(J9:J18) -> 157141 | K19: =SUM(K9:K18) -> 158990 | L19: =SUM(L9:L18) -> 163243 | M19: =SUM(M9:M18) -> 153334
C20: Inventories | I20: 21466 | J20: 25621 | K20: 26486 | L20: 26234 | M20: 23933
C21: Trade Receivables | I21: 7673 | J21: 8100 | K21: 7281 | L21: 6973 | M21: 5851
C22: Receivables From Financial Services | I22: 33670 | J22: 37312 | K22: 39277 | L22: 39320 | M22: 34387
C23: Cash And Cash Equivalents | I23: 23120 | J23: 17679 | K23: 15962 | L23: 14511 | M23: 12254
C24: Marketable Debt Securities And Similar Investments | I24: 6706 | J24: 6237 | K24: 6159 | L24: 7086 | M24: 6940
C25: Other Financial Assets | I25: 3079 | J25: 3453 | K25: 3599 | L25: 2868 | M25: 2852
C26: Income Tax Assets | I26: 0 | J26: 0 | K26: 798 | L26: 1034 | M26: 1257
C27: Other Assets | I27: 4073 | J27: 4472 | K27: 3675 | L27: 3581 | M27: 3645
C28: Assets Held For Sale | I28: 3142 | J28: 0 | K28: 795 | L28: 160 | M28: 11013
B29: Total Current Assets | I29: =SUM(I20:I28) -> 102929 | J29: =SUM(J20:J28) -> 102874 | K29: =SUM(K20:K28) -> 104032 | L29: =SUM(L20:L28) -> 101767 | M29: =SUM(M20:M28) -> 102132
B30: Total Assets | I30: =I19+I29 -> 259831 | J30: =J19+J29 -> 260015 | K30: =K19+K29 -> 263022 | L30: =L19+L29 -> 265010 | M30: =M19+M29 -> 255466
B32: Equity And Liabilities
C33: Share Capital | I33: 3070 | J33: 3070 | K33: 3070 | L33: 3070 | M33: 3070
C34: Capital Reserves | I34: 11723 | J34: 11718 | K34: 11718 | L34: 11718 | M34: 11718
C35: Retained Earnings | I35: 55926 | J35: 67695 | K35: 76670 | L35: 75469 | M35: 77631
C36: Other Reserves | I36: 1232 | J36: 2932 | K36: 2571 | L36: 2368 | M36: 1163
C37: Treasury Shares | I37: 0 | J37: 0 | K37: -2256 | L37: 0 | M37: -325
B38: Equity Attributable To Shareholders Of Mercedes-Benz Group AG | I38: =SUM(I33:I37) -> 71951 | J38: =SUM(J33:J37) -> 85415 | K38: =SUM(K33:K37) -> 91773 | L38: =SUM(L33:L37) -> 92625 | M38: =SUM(M33:M37) -> 93257
C39: Non-Controlling Interests | I39: 1216 | J39: 1125 | K39: 1043 | L39: 1005 | M39: 983
B40: Total Equity | I40: =I38+I39 -> 73167 | J40: =J38+J39 -> 86540 | K40: =K38+K39 -> 92816 | L40: =L38+L39 -> 93630 | M40: =M38+M39 -> 94240
C41: Provisions For Pensions And Similar Obligations | I41: 5359 | J41: 1021 | K41: 1090 | L41: 952 | M41: 807
C42: Provisions For Other Risks | I42: 7909 | J42: 6438 | K42: 7345 | L42: 7332 | M42: 7612
C43: Financing Liabilities | I43: 73543 | J43: 62051 | K43: 63724 | L43: 73487 | M43: 62410
C44: Other Financial Liabilities | I44: 1808 | J44: 2524 | K44: 1642 | L44: 1490 | M44: 1278
C45: Deferred Tax Liabilities | I45: 4488 | J45: 6910 | K45: 7714 | L45: 7497 | M45: 10201
...

Sheet Statement of Cash Flows
D2: Mercedes-Benz Group
B4: Consolidated Statement of Cash Flows
B6: All figures in € millions unless stated | I6: 2021 | J6: =I6+1 -> 2022 | K6: =J6+1 -> 2023 | L6: =K6+1 -> 2024 | M6: =L6+1 -> 2025
B9: Profit Before Income Taxes | I9: 28775 | J9: 20304 | K9: 20084 | L9: 14147 | M9: 6284
B10: Depreciation And Amortization/Impairments | I10: 6980 | J10: 6521 | K10: 6663 | L10: 6772 | M10: 7223
B11: Other Non-Cash Expense And Income | I11: -11503 | J11: -1296 | K11: -2369 | L11: -1362 | M11: -1204
B12: Gains (-)/Losses(+) From Disposals Of Non-Current Assets | I12: -695 | J12: -990 | K12: -92 | L12: 18 | M12: 65
B13: Change In Operating Assets And Liabilities
B14: Inventories | I14: -2561 | J14: -4111 | K14: -2420 | L14: 737 | M14: 724
B15: Trade Receivables And Trade Payables | I15: 1694 | J15: 1029 | K15: 1310 | L15: -1199 | M15: 895
B16: Receivables From Financial Services | I16: 3879 | J16: -5327 | K16: -6125 | L16: 3280 | M16: 5828
B17: Vehicles On Operating Leases | I17: 1428 | J17: 3810 | K17: -640 | L17: -3110 | M17: -4060
B18: Other Operating Assets And Liabilities | I18: -1261 | J18: 358 | K18: 1624 | L18: 986 | M18: 2585
B19: Dividends Received From Equity-Method Investments | I19: 1625 | J19: 1605 | K19: 2056 | L19: 1918 | M19: 1330
B20: Income Taxes Paid | I20: -3812 | J20: -5009 | K20: -5621 | L20: -4452 | M20: -1664
B21: Cash Flow From Operating Activities | I21: =SUM(I9:I20) -> 24549 | J21: =SUM(J9:J20) -> 16894 | K21: =SUM(K9:K20) -> 14470 | L21: =SUM(L9:L20) -> 17735 | M21: =SUM(M9:M20) -> 18006
B23: Acquisitions Of Property, Plant And Equipment | I23: -4579 | J23: -3481 | K23: -3745 | L23: -4039 | M23: -5482
B24: Acquisitions Of Intangible Assets | I24: -2741 | J24: -3418 | K24: -4468 | L24: -4626 | M24: -4260
B25: Cash Inflows From Disposals Of Property, Plant And Equipment And Intangible Assets | I25: 826 | J25: 469 | K25: 285 | L25: 188 | M25: 191
B26: Acquisitions Of Shareholdings | I26: -573 | J26: -849 | K26: -334 | L26: -363 | M26: -304
B27: Cash Inflows From Disposals Of Shareholdings And Other Business Operations | I27: 793 | J27: 3337 | K27: 612 | L27: 716 | M27: 413
B28: Acquisitions Of Marketable Debt Securities And Similar Investments | I28: -5694 | J28: -2622 | K28: -4714 | L28: -6785 | M28: -12303
B29: Cash Inflows From Sales Of Marketable Debt Securities And Similar Investments | I29: 4385 | J29: 3084 | K29: 5021 | L29: 6160 | M29: 12557
B30: Repayment Of Financing Of Daimler's Commercial Vehicles Business | I30: 6853 | J30: 0 | K30: 0 | L30: 0 | M30: 0
B31: Cash And Cash Equivalents Disposed Of From The Deconsolidation Of Daimler's Commercial Vehicles Business | I31: -5489 | J31: 0 | K31: 0 | L31: 0 | M31: 0
B32: Other Cash Flows | I32: -7 | J32: 27 | K32: 28 | L32: -1 | M32: -12
B33: Cash Flow From Investing Activities | I33: =SUM(I23:I32) -> -6226 | J33: =SUM(J23:J32) -> -3453 | K33: =SUM(K23:K32) -> -7315 | L33: =SUM(L23:L32) -> -8750 | M33: =SUM(M23:M32) -> -9200
B35: Change In Short-Term Financing Liabilities | I35: 1463 | J35: 172 | K35: -512 | L35: -3171 | M35: -3558
B36: Additions In Long-Term Financing Liabilities | I36: 42196 | J36: 38429 | K36: 39288 | L36: 38338 | M36: 28598
B37: Repayment Of Long-Term Financing Liabilities | I37: -60859 | J37: -51945 | K37: -39473 | L37: -35355 | M37: -30970
B38: Dividend Paid To Shareholders Of Mercedes-Benz Group Ag | I38: -1444 | J38: -5349 | K38: -5556 | L38: -5486 | M38: -4140
B39: Dividend Paid To Non-Controlling Interests | I39: -366 | J39: -320 | K39: -324 | L39: -239 | M39: -183
B40: Acquisition Of Treasury Shares | I40: 0 | J40: -48 | K40: -1941 | L40: -4921 | M40: -360
B41: Other Cash Flows | I41: -49 | J41: 29 | K41: 127 | L41: 82 | M41: 160
B42: Cash Flow From Financing Activities | I42: =SUM(I35:I41) -> -19059 | J42: =SUM(J35:J41) -> -19032 | K42: =SUM(K35:K41) -> -8391 | L42: =SUM(L35:L41) -> -10752 | M42: =SUM(M35:M41) -> -10453
B44: Effect Of Foreign Exchange-Rate Changes On Cash And Cash Equivalents | I44: 870 | J44: 88 | K44: -471 | L44: 311 | M44: -593
B46: Change In Cash And Cash Equivalents | I46: =I21+I33+I42+I44 -> 134 | J46: =J21+J33+J42+J44 -> -5503 | K46: =K21+K33+K42+K44 -> -1707 | L46: =L21+L33+L42+L44 -> -1456 | M46: =M21+M33+M42+M44 -> -2240
B47: Cash And Cash Equivalents At Beginning Of Year | I47: 23048 | J47: 23182 | K47: 17679 | L47: 15972 | M47: 14516
B48: Less Cash And Cash Equivalents Classified As Assets Held For Sale At Beginning Of Year | I48: 0 | J48: 62 | K48: 0 | L48: 10 | M48: 5
B49: Cash And Cash Equivalents At Beginning Of Year (Consolidated Statement Of Financial Position) | I49: =I47-I48 -> 23048 | J49: =J47-J48 -> 23120 | K49: =K47-K48 -> 17679 | L49: =L47-L48 -> 15962 | M49: =M47-M48 -> 14511
...

Sheet Segment Analysis
D2: Mercedes-Benz Group
B4: Segment Performance & Contribution
B6: All figures in € millions unless stated | I6: 2021 | J6: =I6+1 -> 2022 | K6: =J6+1 -> 2023 | L6: =K6+1 -> 2024 | M6: =L6+1 -> 2025
B8: Mercedes-Benz Cars
C9: Revenue | I9: 96712 | J9: 111601 | K9: 112756 | L9: 107761 | M9: 96407
C10: Adjusted EBIT | I10: 12689 | J10: 16245 | K10: 14252 | L10: 8677 | M10: 4773
C11: Adjusted Return On Sales (RoS) | I11: 0.131 | J11: 0.146 | K11: 0.126 | L11: 0.081 | M11: 0.05
C12: Unit Sales | F12: Millions | I12: 1.94 | J12: 2.04 | K12: 2.04 | L12: 1.98 | M12: 1.8
C13: Top-End Mix | I13: 0.16 | J13: 0.16 | K13: 0.16 | L13: 0.14 | M13: 0.15
B15: Mercedes-Benz Vans
C16: Revenue | I16: 14735 | J16: 17217 | K16: 20288 | L16: 19320 | M16: 17148
C17: Adjusted EBIT | I17: 1229 | J17: 1927 | K17: 3063 | L17: 2825 | M17: 1755
C18: Adjusted Return On Sales (RoS) | I18: 0.083 | J18: 0.112 | K18: 0.151 | L18: 0.146 | M18: 0.102
C19: Unit Sales | F19: Thousands | I19: 386.2 | J19: 415.3 | K19: 447.8 | L19: 405.61 | M19: 359.136
C20: eVan Share | I20: 0.034 | J20: 0.036 | K20: 0.051 | L20: 0.048 | M20: 0.079
B22: Mercedes-Benz Mobility
C23: Portfolio | I23: ='Mobility Analysis'!I10 -> 133687 | J23: ='Mobility Analysis'!J10 -> 132379 | K23: ='Mobility Analysis'!K10 -> 135027 | L23: ='Mobility Analysis'!L10 -> 138095 | M23: ='Mobility Analysis'!M10 -> 128751
C24: Adjusted EBIT | I24: ='Mobility Analysis'!I12 -> 3449 | J24: ='Mobility Analysis'!J12 -> 2428 | K24: ='Mobility Analysis'!K12 -> 1695 | L24: ='Mobility Analysis'!L12 -> 1134 | M24: ='Mobility Analysis'!M12 -> 1267
C25: Adjusted Return On Equity (RoE) | I25: ='Mobility Analysis'!I13 -> 0.22 | J25: ='Mobility Analysis'!J13 -> 0.168 | K25: ='Mobility Analysis'!K13 -> 0.123 | L25: ='Mobility Analysis'!L13 -> 0.087 | M25: ='Mobility Analysis'!M13 -> 0.097
B27: Segment Adjusted EBIT Contribution
C28: Group Adjusted EBIT (Continuing Operations) | I28: 17158 | J28: 20655 | K28: 20004 | L28: 13713 | M28: 8235
C29: Segments Adjusted EBIT | I29: =I10+I17+I24 -> 17367 | J29: =J10+J17+J24 -> 20600 | K29: =K10+K17+K24 -> 19010 | L29: =L10+L17+L24 -> 12636 | M29: =M10+M17+M24 -> 7795
C31: Cars Contribution | I31: =I10/I28 -> 0.73953841 | J31: =J10/J28 -> 0.78649237 | K31: =K10/K28 -> 0.71245751 | L31: =L10/L28 -> 0.63275724 | M31: =M10/M28 -> 0.57959927
C32: Vans Contribution | I32: =I17/I28 -> 0.071628395 | J32: =J17/J28 -> 0.093294602 | K32: =K17/K28 -> 0.15311938 | L32: =L17/L28 -> 0.2060089 | M32: =M17/M28 -> 0.21311475
C33: Mobility Contribution | I33: =I24/I28 -> 0.2010141 | J33: =J24/J28 -> 0.11755023 | K33: =K24/K28 -> 0.084733053 | L33: =L24/L28 -> 0.082695253 | M33: =M24/M28 -> 0.15385549
C34: Reconciliation/Other | I34: =1-(I29/I28) -> -0.012180907 | J34: =1-(J29/J28) -> 0.0026627935 | K34: =1-(K29/K28) -> 0.049690062 | L34: =1-(L29/L28) -> 0.078538613 | M34: =1-(M29/M28) -> 0.05343048
I35: =ROUND(SUM(I31:I34),0) -> 1 | J35: =ROUND(SUM(J31:J34),0) -> 1 | K35: =ROUND(SUM(K31:K34),0) -> 1 | L35: =ROUND(SUM(L31:L34),0) -> 1 | M35: =ROUND(SUM(M31:M34),0) -> 1
B38: Chart - Group Earnings Reset
Q43: Year | R43: =I6 -> 2021 | S43: =J6 -> 2022 | T43: =K6 -> 2023 | U43: =L6 -> 2024 | V43: =M6 -> 2025
Q44: Group Revenue | R44: ='Statement of Income'!I9 -> 133893 | S44: ='Statement of Income'!J9 -> 150017 | T44: ='Statement of Income'!K9 -> 152390 | U44: ='Statement of Income'!L9 -> 145594 | V44: ='Statement of Income'!M9 -> 132214
Q45: Group Adjusted EBIT | R45: =I28 -> 17158 | S45: =J28 -> 20655 | T45: =K28 -> 20004 | U45: =L28 -> 13713 | V45: =M28 -> 8235
Q47: Year | R47: =R43 -> 2021 | S47: =S43 -> 2022 | T47: =T43 -> 2023 | U47: =U43 -> 2024 | V47: =V43 -> 2025
Q48: Group Revenue Index | R48: =R44/$R$44*100 -> 100 | S48: =S44/$R$44*100 -> 112.04245 | T48: =T44/$R$44*100 -> 113.81476 | U48: =U44/$R$44*100 -> 108.73907 | V48: =V44/$R$44*100 -> 98.746014
Q49: Group Adjusted EBIT Index | R49: =R45/$R$45*100 -> 100 | S49: =S45/$R$45*100 -> 120.38116 | T49: =T45/$R$45*100 -> 116.58701 | U49: =U45/$R$45*100 -> 79.921902 | V49: =V45/$R$45*100 -> 47.995104
B68: Chart - Volume Shock
Q73: Year | R73: =$R$47 -> 2021 | S73: =$R$47 -> 2021 | T73: =$R$47 -> 2021 | U73: =$R$47 -> 2021 | V73: =$R$47 -> 2021
Q74: Cars Volume | R74: =I12 -> 1.94 | S74: =J12 -> 2.04 | T74: =K12 -> 2.04 | U74: =L12 -> 1.98 | V74: =M12 -> 1.8
Q75: Vans Volume | R75: =I19/1000 -> 0.3862 | S75: =J19/1000 -> 0.4153 | T75: =K19/1000 -> 0.4478 | U75: =L19/1000 -> 0.40561 | V75: =M19/1000 -> 0.359136
Q77: Note: The figures are in millions
B98: Chart - Profitability Divergence
...

Sheet Mobility Analysis
D2: Mercedes-Benz Group
B4: Mobility Analysis
B6: All figures in € millions unless stated | I6: 2021 | J6: =I6+1 -> 2022 | K6: =J6+1 -> 2023 | L6: =K6+1 -> 2024 | M6: =L6+1 -> 2025
B8: Portfolio & Balance Sheet
C9: New Business | I9: 63631 | J9: 58031 | K9: 62014 | L9: 59486 | M9: 55917
C10: Financing / Leasing Portfolio | I10: 133687 | J10: 132379 | K10: 135027 | L10: 138095 | M10: 128751
C11: Financing Liabilities | I11: 121966 | J11: 119386 | K11: 122416 | L11: 126197 | M11: 107938
C12: Adjusted EBIT | I12: 3449 | J12: 2428 | K12: 1695 | L12: 1134 | M12: 1267
C13: Adjusted ROE | I13: 0.22 | J13: 0.168 | K13: 0.123 | L13: 0.087 | M13: 0.097
B16: Risk Indicators
C17: Cost Of Credit Risk / (Benefit) | I17: -112 | J17: 215 | K17: 358 | L17: 520 | M17: 685
C18: Residual-Value Effects – Analytical Direction | I18: Positive | J18: Positive | K18: Neutral | L18: Negative | M18: Negative
B21: *Residual-Value Effects direction is an analytical assessment based on Mercedes' 'Remarketing Results' disclosures.
B27: Chart - Mobility Profitability Normalization

Sheet Capital Intensity
D2: Mercedes-Benz Group
B4: Capital Intensity
B6: All figures in € millions unless stated | I6: 2021 | J6: =I6+1 -> 2022 | K6: =J6+1 -> 2023 | L6: =K6+1 -> 2024 | M6: =L6+1 -> 2025
B8: Group Metrics
C9: Group Revenue | I9: ='Statement of Income'!I9 -> 133893 | J9: ='Statement of Income'!J9 -> 150017 | K9: ='Statement of Income'!K9 -> 152390 | L9: ='Statement of Income'!L9 -> 145594 | M9: ='Statement of Income'!M9 -> 132214
C11: PP&E Additions | I11: =-'Statement of Cash Flows'!I23 -> 4579 | J11: =-'Statement of Cash Flows'!J23 -> 3481 | K11: =-'Statement of Cash Flows'!K23 -> 3745 | L11: =-'Statement of Cash Flows'!L23 -> 4039 | M11: =-'Statement of Cash Flows'!M23 -> 5482
C12: CapEx Intensity | I12: =I11/I$9 -> 0.03419895 | J12: =J11/J$9 -> 0.023204037 | K12: =K11/K$9 -> 0.024575103 | L12: =L11/L$9 -> 0.027741528 | M12: =M11/M$9 -> 0.041463083
C14: Total R&D Expenditure | I14: 9105 | J14: 8541 | K14: 9996 | L14: 9717 | M14: 9680
C15: Capitalized R&D Costs | I15: 2435 | J15: 2939 | K15: 3766 | L15: 4137 | M15: 3625
C16: Capitalized R&D Intensity | I16: =I15/I$9 -> 0.018186164 | J16: =J15/J$9 -> 0.019591113 | K16: =K15/K$9 -> 0.024712908 | L16: =L15/L$9 -> 0.028414632 | M16: =M15/M$9 -> 0.027417671
C17: R&D Capitalization Rate | I17: =I15/I14 -> 0.26743548 | J17: =J15/J14 -> 0.34410491 | K17: =K15/K14 -> 0.3767507 | L17: =L15/L14 -> 0.42574869 | M17: =M15/M14 -> 0.37448347
C19: Intangible Assets Additions | I19: =-'Statement of Cash Flows'!I24 -> 2741 | J19: =-'Statement of Cash Flows'!J24 -> 3418 | K19: =-'Statement of Cash Flows'!K24 -> 4468 | L19: =-'Statement of Cash Flows'!L24 -> 4626 | M19: =-'Statement of Cash Flows'!M24 -> 4260
C20: Total Investment | I20: =I11+I19 -> 7320 | J20: =J11+J19 -> 6899 | K20: =K11+K19 -> 8213 | L20: =L11+L19 -> 8665 | M20: =M11+M19 -> 9742
C21: Total Investment Intensity | I21: =I20/I$9 -> 0.05467052 | J21: =J20/J$9 -> 0.045988121 | K21: =K20/K$9 -> 0.053894613 | L21: =L20/L$9 -> 0.059514815 | M21: =M20/M$9 -> 0.073683574
C23: Depreciation & Amortization (D&A) | I23: ='Statement of Cash Flows'!I10 -> 6980 | J23: ='Statement of Cash Flows'!J10 -> 6521 | K23: ='Statement of Cash Flows'!K10 -> 6663 | L23: ='Statement of Cash Flows'!L10 -> 6772 | M23: ='Statement of Cash Flows'!M10 -> 7223
C25: Reinvestment Ratio | I25: =I20/I23 -> 1.0487106 | J25: =J20/J23 -> 1.0579666 | K25: =K20/K23 -> 1.2326279 | L25: =L20/L23 -> 1.2795334 | M25: =M20/M23 -> 1.3487471
B27: Industrial Metrics (Cars + Vans)
C28: Industrial Revenue (Cars & Vans) | I28: ='Segment Analysis'!I9+'Segment Analysis'!I16 -> 111447 | J28: ='Segment Analysis'!J9+'Segment Analysis'!J16 -> 128818 | K28: ='Segment Analysis'!K9+'Segment Analysis'!K16 -> 133044 | L28: ='Segment Analysis'!L9+'Segment Analysis'!L16 -> 127081 | M28: ='Segment Analysis'!M9+'Segment Analysis'!M16 -> 113555
C30: Adjusted EBIT | I30: ='Segment Analysis'!I10+'Segment Analysis'!I17 -> 13918 | J30: ='Segment Analysis'!J10+'Segment Analysis'!J17 -> 18172 | K30: ='Segment Analysis'!K10+'Segment Analysis'!K17 -> 17315 | L30: ='Segment Analysis'!L10+'Segment Analysis'!L17 -> 11502 | M30: ='Segment Analysis'!M10+'Segment Analysis'!M17 -> 6528
C31: Adjusted EBIT Margin | I31: =I30/I28 -> 0.12488447 | J31: =J30/J28 -> 0.14106724 | K31: =K30/K28 -> 0.13014491 | L31: =L30/L28 -> 0.090509203 | M31: =M30/M28 -> 0.057487561
C33: Industrial FCF | I33: 7880 | J33: 8128 | K33: 11316 | L33: 9152 | M33: 5414
C34: Adjusted Industrial FCF | I34: 10125 | J34: 9294 | K34: 11720 | L34: 9421 | M34: 5856
C35: Adjusted Industrial FCF Margin | I35: =I34/I28 -> 0.090850359 | J35: =J34/J28 -> 0.072148302 | K35: =K34/K28 -> 0.088091158 | L35: =L34/L28 -> 0.07413382 | M35: =M34/M28 -> 0.051569724
B39: Chart - Product & Technology Investment

Sheet ROIC Analysis
D2: Mercedes-Benz Group
B4: ROIC Analysis (Industrial Business - Cars & Vans)
B6: All figures in € millions unless stated | I6: 2021 | J6: =I6+1 -> 2022 | K6: =J6+1 -> 2023 | L6: =K6+1 -> 2024 | M6: =L6+1 -> 2025
B8: Industrial ROIC Core Metrics
C9: Industrial Revenue (Cars + Vans) | I9: ='Capital Intensity'!I28 -> 111447 | J9: ='Capital Intensity'!J28 -> 128818 | K9: ='Capital Intensity'!K28 -> 133044 | L9: ='Capital Intensity'!L28 -> 127081 | M9: ='Capital Intensity'!M28 -> 113555
C10: Industrial Adjusted EBIT | I10: ='Segment Analysis'!I10+'Segment Analysis'!I17 -> 13918 | J10: ='Segment Analysis'!J10+'Segment Analysis'!J17 -> 18172 | K10: ='Segment Analysis'!K10+'Segment Analysis'!K17 -> 17315 | L10: ='Segment Analysis'!L10+'Segment Analysis'!L17 -> 11502 | M10: ='Segment Analysis'!M10+'Segment Analysis'!M17 -> 6528
C11: Analytical Tax rate | I11: 0.3 | J11: 0.3 | K11: 0.3 | L11: 0.3 | M11: 0.3
C12: Industrial NOPAT | I12: =I10*(1-I11) -> 9742.6 | J12: =J10*(1-J11) -> 12720.4 | K12: =K10*(1-K11) -> 12120.5 | L12: =L10*(1-L11) -> 8051.4 | M12: =M10*(1-M11) -> 4569.6
C13: NOPAT Margin | I13: =I12/I9 -> 0.087419132 | J13: =J12/J9 -> 0.09874707 | K13: =K12/K9 -> 0.09110144 | L13: =L12/L9 -> 0.063356442 | M13: =M12/M9 -> 0.040241293
C14: Average Net Assets (Invested Capital) | I14: 33866 | J14: 39074 | K14: 42660 | L14: 43537 | M14: 40858
C15: Capital Turnover | I15: =I9/I14 -> 3.2908227 | J15: =J9/J14 -> 3.2967702 | K15: =K9/K14 -> 3.118706 | L15: =L9/L14 -> 2.9189195 | M15: =M9/M14 -> 2.7792599
C16: Industrial ROIC | I16: =I12/I14 -> 0.28768086 | J16: =J12/J14 -> 0.3255464 | K16: =K12/K14 -> 0.28411861 | L16: =L12/L14 -> 0.18493236 | M16: =M12/M14 -> 0.11184101
B18: Analytical Year-End Operating Capital Bridge
C19: PP&E | L19: 26181 | M19: 26946
C20: Operating Working Capital | L20: 22121 | M20: 19256
C21: Other Operating Assets | L21: 18871 | M21: 20065
C22: Less: Operating Liabilities | L22: -25534 | M22: -25406
C23: Year-End Reconciliation | L23: =SUM(L19:L22) -> 41639 | M23: =SUM(M19:M22) -> 40861
B25: NOPAT | L25: =L12 -> 8051.4 | M25: =M12 -> 4569.6
B26: NOPAT Margin | L26: =L13 -> 0.063356442 | M26: =M13 -> 0.040241293
B27: Capital Turnover | L27: =L15 -> 2.9189195 | M27: =M15 -> 2.7792599
B28: ROIC | L28: =L16 -> 0.18493236 | M28: =M16 -> 0.11184101
B30: ROIC Absolute Change - Percentage Points | M30: =(M28-L28)*100 -> -7.3091346
B31: ROIC Relative Change | M31: =(M28/L28)-1 -> -0.39523287
B35: Chart - ROIC

Sheet Operating Data
D2: Mercedes-Benz Group
B4: Operating Data
B6: All figures in € millions unless stated | I6: 2021 | J6: =I6+1 -> 2022 | K6: =J6+1 -> 2023 | L6: =K6+1 -> 2024 | M6: =L6+1 -> 2025
B8: Mercedes-Benz Cars Regional Unit Sales
C9: Europe | F9: Units | L9: 641792 | M9: 635072
C10: North America | F10: Units | L10: 365358 | M10: 320552
C11: Asia | F11: Units | L11: 892147 | M11: 746981
C12: China | F12: Units | L12: 683568 | M12: 551932
C13: Rest of Asia | F13: Units | L13: =L11-L12 -> 208579 | M13: =M11-M12 -> 195049
C14: Other Markets | F14: Units | L14: 84106 | M14: 98686
C15: Total Unit Sales | L15: =L9+L10+L11+L14 -> 1983403 | M15: =M9+M10+M11+M14 -> 1801291
C17: YoY Change
C18: Europe | M18: =(M9/L9)-1 -> -0.010470682
C19: North america | M19: =(M10/L10)-1 -> -0.12263588
C20: China | M20: =(M12/L12)-1 -> -0.19257192
C21: Rest of Asia | M21: =(M13/L13)-1 -> -0.064867508
B23: Cars Adjusted EBIT Bridge (2024 -> 2025)
C24: 2024 Adjusted EBIT | M24: ='Segment Analysis'!L10 -> 8677
C25: Volume, Structure, Net Pricing | M25: -5815
C26: Foreign Exchange Rates | M26: -1498
C27: Industrial Performance | M27: 2730
C28: Selling Expenses | M28: 677
C29: General Administrative Expenses | M29: 185
C30: Research & Non-Capitalized Development Costs | M30: -42
C31: Other | M31: -141
C32: 2025 Adjusted EBIT | M32: =SUM(M24:M31) -> 4773
B37: Operating Data
B39: All figures in € millions unless stated | I39: 2021 | J39: =I39+1 -> 2022 | K39: =J39+1 -> 2023 | L39: =K39+1 -> 2024 | M39: =L39+1 -> 2025
B41: Electrification Trajectory
C42: Cars xEV Share (Electrified Vehicles) | I42: 0.117 | J42: 0.16 | K42: 0.197 | L42: 0.185 | M42: 0.205
C43: Original 2021 Ambition | I43: 0.5 | J43: 0.5 | K43: 0.5 | L43: 0.5 | M43: 0.5
C44: BEV Unit Sales (All-Electric Vehicles) | I44: 89500 | J44: 149200 | K44: 240668 | L44: 185059 | M44: 168823
B47: Industrial FCF | I47: ='Capital Intensity'!I33 -> 7880 | J47: ='Capital Intensity'!J33 -> 8128 | K47: ='Capital Intensity'!K33 -> 11316 | L47: ='Capital Intensity'!L33 -> 9152 | M47: ='Capital Intensity'!M33 -> 5414
B48: Cash Returns
C49: Dividend Paid To Shareholders Of Mercedes-Benz Group Ag | I49: =-'Statement of Cash Flows'!I38 -> 1444 | J49: =-'Statement of Cash Flows'!J38 -> 5349 | K49: =-'Statement of Cash Flows'!K38 -> 5556 | L49: =-'Statement of Cash Flows'!L38 -> 5486 | M49: =-'Statement of Cash Flows'!M38 -> 4140
C50: Dividend Paid To Non-Controlling Interests | I50: =-'Statement of Cash Flows'!I39 -> 366 | J50: =-'Statement of Cash Flows'!J39 -> 320 | K50: =-'Statement of Cash Flows'!K39 -> 324 | L50: =-'Statement of Cash Flows'!L39 -> 239 | M50: =-'Statement of Cash Flows'!M39 -> 183
C51: Acquisition Of Treasury Shares | I51: =-'Statement of Cash Flows'!I40 -> 0 | J51: =-'Statement of Cash Flows'!J40 -> 48 | K51: =-'Statement of Cash Flows'!K40 -> 1941 | L51: =-'Statement of Cash Flows'!L40 -> 4921 | M51: =-'Statement of Cash Flows'!M40 -> 360
C52: Returns to Mercedes-Benz Group AG Shareholders | I52: =I49+I51 -> 1444 | J52: =J49+J51 -> 5397 | K52: =K49+K51 -> 7497 | L52: =L49+L51 -> 10407 | M52: =M49+M51 -> 4500
C53: Payout Ratio (% of FCF) | I53: =I52/I47 -> 0.18324873 | J53: =J52/J47 -> 0.66400098 | K53: =K52/K47 -> 0.66251326 | L53: =L52/L47 -> 1.1371285 | M53: =M52/M47 -> 0.83117843
C55: Total Distributions & Treasury shares | I55: =SUM(I49:I51) -> 1810 | J55: =SUM(J49:J51) -> 5717 | K55: =SUM(K49:K51) -> 7821 | L55: =SUM(L49:L51) -> 10646 | M55: =SUM(M49:M51) -> 4683
...

Sheet Peer Comparison
D2: Mercedes-Benz Group
B4: Peer Comparison
B6: All figures in € millions unless stated | I6: 2021 | J6: =I6+1 -> 2022 | K6: =J6+1 -> 2023 | L6: =K6+1 -> 2024 | M6: =L6+1 -> 2025
B8: BEV Volume
C9: Mercedes-Benz Cars | F9: Units | M9: ='Operating Data'!M44 -> 168823
C10: YoY Growth | M10: -0.088
C11: BMW Group Automobiles | F11: Units | M11: 442059
C12: YoY Growth | M12: 0.036
B14: Core Automotive Margin Compression
C15: Mercedes-Benz Cars (EBIT Margin) | L15: 0.079 | M15: 0.037
C16: BMW Group Automobiles (EBIT Margin) | L16: 0.063 | M16: 0.053
B18: Mercedes-Benz Cars
C19: Total Volume YoY | M19: -0.092
C20: China Volume YoY | M20: -0.192
B22: BMW Group Automobiles
C23: Total Volume YoY | M23: 0.005
C24: China Volume YoY | M24: -0.125
B30: Chart - Peer Comparison
B58: *BMW Group figures refer to the Group's Automobiles business, including BMW, MINI and Rolls-Royce, Mercedes-Benz figures refer to Mercedes-Benz Cars.
B60: Chart - Automotive Margin Gap
B88: *BMW Group figures refer to the Group's Automobiles business, including BMW, MINI and Rolls-Royce, Mercedes-Benz figures refer to Mercedes-Benz Cars.

Sheet Outlook & Valuation
D2: Mercedes-Benz Group
B4: Outlook & Valuation
B6: Mercedes-Benz Cars & Vans | J6: Peak | L6: Solid
J7: Cars | K7: Vans | L7: Cars | M7: Vans
B8: Peak Margin (2022-2023) | E8: Adjusted RoS | J8: ='Segment Analysis'!J11 -> 0.146 | K8: ='Segment Analysis'!K18 -> 0.151 | L8: =J8 -> 0.146 | M8: =K8 -> 0.151
B9: 2025 Actual | E9: Adjusted RoS | J9: ='Segment Analysis'!M11 -> 0.05 | K9: ='Segment Analysis'!M18 -> 0.102 | L9: =J9 -> 0.05 | M9: =K9 -> 0.102
B10: 2026 Guidance | E10: Adjusted RoS | J10: 0.05 | K10: 0.1 | L10: 0.03 | M10: 0.08
B13: 2025 Reported EPS (€ ) | M13: 5.34
J15: P/E Assumption | L15: Implied Value
J16: 6 | L16: 32
J17: 7 | L17: 37.4
J18: 8 | L18: 42.7
J19: 9 | L19: 48.1
J20: 10 | L20: 53.4
B31: Chart - Margins Trajectory
